<?xml version="1.0" ?>
<!-- =================================================================================== -->
<!-- |    This document was autogenerated by xacro from x_leopard_wheeled_all.xacro    | -->
<!-- |    EDITING THIS FILE BY HAND IS NOT RECOMMENDED                                 | -->
<!-- =================================================================================== -->
<robot name="x_leopard">

    <link name="body">
        <inertial>
            <origin rpy="0 0 0" xyz="-0.00458458 0.00306684 0.00947989"/>
            <mass value="5.76855"/>
            <inertia ixx="0.0478275" ixy="0.000562337" ixz="0.000154559" iyy="0.105776" iyz="0.00054122"
                     izz="0.121012"/>
        </inertial>
        <visual>
            <origin rpy="3.1415 0 0" xyz="0 0 0"/>
            <geometry>
                <mesh filename="package://max/meshes/visual/body.dae"/>
            </geometry>
            <material name="">
                <color rgba="0.0 0.0 0.0 1.0"/>
            </material>
        </visual>
        <collision>
            <origin rpy="0 0 0" xyz="0 0 0"/>
            <geometry>
                <box size="0.283 0.205 0.11"/>
            </geometry>
        </collision>
    </link>

    <!-- FR leg -->
    <link name="link_FR1">
        <inertial>
            <origin rpy="0 0 0" xyz="-0.0028696 0.00034586 -0.00046692"/>
            <mass value="0.60318142"/>
            <inertia ixx="0.00036534" ixy="-0.00000156" ixz="-0.00000493" iyy="0.00064755" iyz="0.00000517"
                     izz="0.00041528"/>
        </inertial>
        <visual>
            <origin rpy="0 0 0" xyz="0 0 0"/>
            <geometry>
                <mesh filename="package://max/meshes/visual/link_FR1.STL"/>
            </geometry>
            <material name="">
                <color rgba="1 1 1 1"/>
            </material>
        </visual>
        <collision>
            <origin rpy="1.5707963267948966 0 0" xyz="0 0 0"/>
            <geometry>
                <cylinder length="0.0255" radius="0.047"/>
            </geometry>
        </collision>
    </link>

    <joint name="joint_FR1" type="revolute">
        <origin rpy="0 0 0" xyz="0.195 -0.06 0"/>
        <parent link="body"/>
        <child link="link_FR1"/>
        <axis xyz="1 0 0"/>
        <limit effort="18" lower="-0.872" upper="0.697" velocity="20"/>
        <dynamics damping="0.1" friction="0.5"/>
    </joint>

    <link name="link_FR2">
        <inertial>
            <origin rpy="0 0 0" xyz="-0.000703565074415824 0.0258167471878678 -0.0273471174219229"/>
            <mass value="0.87782621"/>
            <inertia ixx="0.00362810" ixy="-0.00000033" ixz="0.00001632" iyy="0.00369602" iyz="0.00052212"
                     izz="0.00075378"/>
        </inertial>
        <visual>
            <origin rpy="0 0 0" xyz="0 0 0"/>
            <geometry>
                <mesh filename="package://max/meshes/visual/link_FR2.STL"/>
            </geometry>
            <material name="">
                <color rgba="1 1 1 1"/>
            </material>
        </visual>
        <collision>
            <origin rpy="0 1.5707963267948966 0" xyz="0 0 -0.1"/>
            <geometry>
                <box size="0.2 0.025 0.035"/>
            </geometry>
        </collision>
        <collision>
            <origin rpy="1.5707963267948966 0 0" xyz="0 0 0"/>
            <geometry>
                <cylinder length="0.025" radius="0.023"/>
            </geometry>
        </collision>
        <collision>
            <origin rpy="1.5707963267948966 0 0" xyz="0 0.030 0"/>
            <geometry>
                <cylinder length="0.025" radius="0.047"/>
            </geometry>
        </collision>
    </link>

    <joint name="joint_FR2" type="revolute">
        <origin rpy="0 0 0" xyz="0 -0.09 0"/>
        <parent link="link_FR1"/>
        <child link="link_FR2"/>
        <axis xyz="0 -1 0"/>
        <limit effort="18" lower="-4.3633" upper="1.2217" velocity="20"/>
        <dynamics damping="0.1" friction="0.5"/>
    </joint>

    <link name="link_FR3">
        <inertial>
            <origin rpy="0 0 0" xyz="0.00154910870409444 1.43664953849987E-07 -0.124416339725706"/>
            <mass value="0.16887830"/>
            <inertia ixx="0.00151605" ixy="0" ixz="0.00007039" iyy="0.00153030" iyz="-0.00000013" izz="0.00003410"/>
        </inertial>
        <visual>
            <origin rpy="0 0 0" xyz="0 0 0"/>
            <geometry>
                <mesh filename="package://max/meshes/visual/link_FR3.STL"/>
            </geometry>
            <material name="">
                <color rgba="1 1 1 1"/>
            </material>
        </visual>
        <collision>
            <origin rpy="0 1.5707963267948966 0" xyz="0 0 -0.105"/>
            <geometry>
                <box size="0.24 0.02 0.018"/>
            </geometry>
        </collision>
    </link>

    <joint name="joint_FR3" type="revolute">
        <origin rpy="0 0 0" xyz="0 0 -0.2115"/>
        <parent link="link_FR2"/>
        <child link="link_FR3"/>
        <axis xyz="0 -1 0"/>
        <limit effort="18" lower="-2.4496" upper="2.5440" velocity="33"/>
        <dynamics damping="0.1" friction="0.5"/>
    </joint>

    <link name="link_FR4">
        <inertial>
            <origin rpy="0 0 0" xyz="0 0 0"/>
            <mass value="0"/>
            <inertia ixx="0" ixy="0" ixz="0" iyy="0" iyz="0" izz="0"/>
        </inertial>
        <visual>
            <origin rpy="0 0 0" xyz="0 0 0"/>
            <geometry>
                <sphere radius="0.001"/>
            </geometry>
        </visual>
        <collision>
            <origin rpy="0 0 0" xyz="0 0 0"/>
            <geometry>
                <sphere radius="0.025"/>
            </geometry>
        </collision>
    </link>

    <joint name="joint_FR4" type="fixed">
        <origin rpy="0 0 0" xyz="0 0 -0.24"/>
        <parent link="link_FR3"/>
        <child link="link_FR4"/>
    </joint>

    <link name="link_FRW">
        <inertial>
            <origin rpy="0 0 0" xyz="0 0 0"/>
            <mass value="0.0629341609141129"/>
            <inertia ixx="0.00001749" ixy="0" ixz="0" iyy="0.00002918" iyz="0" izz="0.00001749"/>
        </inertial>
        <visual>
            <origin rpy="0 0 0" xyz="0 0 0"/>
            <geometry>
                <mesh filename="package://max/meshes/visual/link_FRW.STL"/>
            </geometry>
            <material name="">
                <color rgba="1 1 1 1"/>
            </material>
        </visual>
        <collision>
            <origin rpy="1.5707963267948966 0 0" xyz="0 0 0"/>
            <geometry>
                <cylinder length="0.012" radius="0.028"/>
            </geometry>
        </collision>
    </link>

    <joint name="joint_FRW" type="fixed">
        <origin rpy="0 0 0" xyz="0 -0.0355 -0.2115"/>
        <parent link="link_FR2"/>
        <child link="link_FRW"/>
        <axis xyz="0 -1 0"/>
        <limit effort="18" lower="-214700000" upper="214700000" velocity="33"/>
        <dynamics damping="0.8" friction="0.5"/>
    </joint>

    <!-- FL leg -->
    <link name="link_FL1">
        <inertial>
            <origin rpy="0 0 0" xyz="-0.0028696 -0.00034586 -0.00046692"/>
            <mass value="0.60318142"/>
            <inertia ixx="0.00036534" ixy="0.00000156" ixz="-0.00000493" iyy="0.00064755" iyz="-0.00000517"
                     izz="0.00041528"/>
        </inertial>
        <visual>
            <origin rpy="0 0 0" xyz="0 0 0"/>
            <geometry>
                <mesh filename="package://max/meshes/visual/link_FL1.STL"/>
            </geometry>
            <material name="">
                <color rgba="1 1 1 1"/>
            </material>
        </visual>
        <collision>
            <origin rpy="1.5707963267948966 0 0" xyz="0 0 0"/>
            <geometry>
                <cylinder length="0.0255" radius="0.047"/>
            </geometry>
        </collision>
    </link>

    <joint name="joint_FL1" type="revolute">
        <origin rpy="0 0 0" xyz="0.195 0.06 0"/>
        <parent link="body"/>
        <child link="link_FL1"/>
        <axis xyz="1 0 0"/>
        <limit effort="18" lower="-0.697" upper="0.872" velocity="20"/>
        <dynamics damping="0.1" friction="0.5"/>
    </joint>

    <link name="link_FL2">
        <inertial>
            <origin rpy="0 0 0" xyz="-0.000703565074415824 -0.0258167471878678 -0.0273471174219229"/>
            <mass value="0.87782621"/>
            <inertia ixx="0.00362810" ixy="0.00000033" ixz="0.00001632" iyy="0.00369602" iyz="-0.00052212"
                     izz="0.00075378"/>
        </inertial>
        <visual>
            <origin rpy="0 0 0" xyz="0 0 0"/>
            <geometry>
                <mesh filename="package://max/meshes/visual/link_FL2.STL"/>
            </geometry>
            <material name="">
                <color rgba="1 1 1 1"/>
            </material>
        </visual>
        <collision>
            <origin rpy="0 1.5707963267948966 0" xyz="0 0 -0.1"/>
            <geometry>
                <box size="0.2 0.025 0.035"/>
            </geometry>
        </collision>
        <collision>
            <origin rpy="1.5707963267948966 0 0" xyz="0 0 0"/>
            <geometry>
                <cylinder length="0.025" radius="0.023"/>
            </geometry>
        </collision>
        <collision>
            <origin rpy="1.5707963267948966 0 0" xyz="0 -0.030 0"/>
            <geometry>
                <cylinder length="0.025" radius="0.047"/>
            </geometry>
        </collision>
    </link>

    <joint name="joint_FL2" type="revolute">
        <origin rpy="0 0 0" xyz="0 0.09 0"/>
        <parent link="link_FL1"/>
        <child link="link_FL2"/>
        <axis xyz="0 -1 0"/>
        <limit effort="18" lower="-4.3633" upper="1.2217" velocity="20"/>
        <dynamics damping="0.1" friction="0.5"/>
    </joint>

    <link name="link_FL3">
        <inertial>
            <origin rpy="0 0 0" xyz="0.00154910870409444 1.43664953849987E-07 -0.124416339725706"/>
            <mass value="0.16887830"/>
            <inertia ixx="0.00151605" ixy="0" ixz="0.00007039" iyy="0.00153030" iyz="-0.00000013" izz="0.00003410"/>
        </inertial>
        <visual>
            <origin rpy="0 0 0" xyz="0 0 0"/>
            <geometry>
                <mesh filename="package://max/meshes/visual/link_FL3.STL"/>
            </geometry>
            <material name="">
                <color rgba="1 1 1 1"/>
            </material>
        </visual>
        <collision>
            <origin rpy="0 1.5707963267948966 0" xyz="0 0 -0.12"/>
            <geometry>
                <box size="0.24 0.02 0.018"/>
            </geometry>
        </collision>
    </link>

    <joint name="joint_FL3" type="revolute">
        <origin rpy="0 0 0" xyz="0 0 -0.2115"/>
        <parent link="link_FL2"/>
        <child link="link_FL3"/>
        <axis xyz="0 -1 0"/>
        <limit effort="18" lower="-2.4496" upper="2.5440" velocity="33"/>
        <dynamics damping="0.1" friction="0.5"/>
    </joint>

    <link name="link_FL4">
        <inertial>
            <origin rpy="0 0 0" xyz="0 0 0"/>
            <mass value="0"/>
            <inertia ixx="0" ixy="0" ixz="0" iyy="0" iyz="0" izz="0"/>
        </inertial>
        <visual>
            <origin rpy="0 0 0" xyz="0 0 0"/>
            <geometry>
                <sphere radius="0.001"/>
            </geometry>
        </visual>
        <collision>
            <origin rpy="0 0 0" xyz="0 0 0"/>
            <geometry>
                <sphere radius="0.025"/>
            </geometry>
        </collision>
    </link>

    <joint name="joint_FL4" type="fixed">
        <origin rpy="0 0 0" xyz="0 0 -0.24"/>
        <parent link="link_FL3"/>
        <child link="link_FL4"/>
    </joint>

    <link name="link_FLW">
        <inertial>
            <origin rpy="0 0 0" xyz="0 0 0"/>
            <mass value="0.0629341609141129"/>
            <inertia ixx="0.00001749" ixy="0" ixz="0" iyy="0.00002918" iyz="0" izz="0.00001749"/>
        </inertial>
        <visual>
            <origin rpy="0 0 0" xyz="0 0 0"/>
            <geometry>
                <mesh filename="package://max/meshes/visual/link_FLW.STL"/>
            </geometry>
            <material name="">
                <color rgba="1 1 1 1"/>
            </material>
        </visual>
        <collision>
            <origin rpy="1.5707963267948966 0 0" xyz="0 0 0"/>
            <geometry>
                <cylinder length="0.012" radius="0.028"/>
            </geometry>
        </collision>
    </link>

    <joint name="joint_FLW" type="fixed">
        <origin rpy="0 0 0" xyz="0 0.0355 -0.2115"/>
        <parent link="link_FL2"/>
        <child link="link_FLW"/>
        <axis xyz="0 -1 0"/>
        <limit effort="18" lower="-214700000" upper="214700000" velocity="33"/>
        <dynamics damping="0.8" friction="0.5"/>
    </joint>

    <!-- HR leg -->
    <link name="link_HR1">
        <inertial>
            <origin rpy="0 0 0" xyz="0.0028696 0.00034586 -0.00046692"/>
            <mass value="0.60318142"/>
            <inertia ixx="0.00036534" ixy="0.00000156" ixz="0.00000493" iyy="0.00064755" iyz="0.00000517"
                     izz="0.00041528"/>
        </inertial>
        <visual>
            <origin rpy="0 0 0" xyz="0 0 0"/>
            <geometry>
                <mesh filename="package://max/meshes/visual/link_HR1.STL"/>
            </geometry>
            <material name="">
                <color rgba="1 1 1 1"/>
            </material>
        </visual>
        <collision>
            <origin rpy="1.5707963267948966 0 0" xyz="0 0 0"/>
            <geometry>
                <cylinder length="0.0255" radius="0.047"/>
            </geometry>
        </collision>
    </link>

    <joint name="joint_HR1" type="revolute">
        <origin rpy="0 0 0" xyz="-0.195 -0.06 0"/>
        <parent link="body"/>
        <child link="link_HR1"/>
        <axis xyz="1 0 0"/>
        <limit effort="18" lower="-0.872" upper="0.697" velocity="20"/>
        <dynamics damping="0.1" friction="0.5"/>
    </joint>

    <link name="link_HR2">
        <inertial>
            <origin rpy="0 0 0" xyz="-0.00077477 0.02622481 -0.02560268"/>
            <mass value="0.89043408"/>
            <inertia ixx="0.00366698" ixy="0.00004816" ixz="-0.00007841" iyy="0.00417229" iyz="0.00046644"
                     izz="0.00119996"/>
        </inertial>
        <visual>
            <origin rpy="0 0 0" xyz="0 0 0"/>
            <geometry>
                <mesh filename="package://max/meshes/visual/link_HR2.STL"/>
            </geometry>
            <material name="">
                <color rgba="1 1 1 1"/>
            </material>
        </visual>
        <collision>
            <origin rpy="0 1.5707963267948966 0" xyz="0 0 -0.1"/>
            <geometry>
                <box size="0.2 0.025 0.035"/>
            </geometry>
        </collision>
        <collision>
            <origin rpy="1.5707963267948966 0 0" xyz="0 0 0"/>
            <geometry>
                <cylinder length="0.025" radius="0.023"/>
            </geometry>
        </collision>
        <collision>
            <origin rpy="1.5707963267948966 0 0" xyz="0 0.030 0"/>
            <geometry>
                <cylinder length="0.025" radius="0.047"/>
            </geometry>
        </collision>
    </link>

    <joint name="joint_HR2" type="revolute">
        <origin rpy="0 0 0" xyz="0 -0.09 0"/>
        <parent link="link_HR1"/>
        <child link="link_HR2"/>
        <axis xyz="0 -1 0"/>
        <limit effort="18" lower="-4.3633" upper="1.2217" velocity="20"/>
        <dynamics damping="0.1" friction="0.5"/>
    </joint>

    <link name="link_HR3">
        <inertial>
            <origin rpy="0 0 0" xyz="0.00171417901871168 -0.000158421724618441 -0.0867126641820617"/>
            <mass value="0.28839466"/>
            <inertia ixx="0.00208102" ixy="-0.00000004" ixz="0.00008280" iyy="0.00209717" iyz="-0.00000423"
                     izz="0.00006551"/>
        </inertial>
        <visual>
            <origin rpy="0 0 0" xyz="0 0 0"/>
            <geometry>
                <mesh filename="package://max/meshes/visual/link_HR3.STL"/>
            </geometry>
            <material name="">
                <color rgba="1 1 1 1"/>
            </material>
        </visual>
        <collision>
            <origin rpy="0 1.5707963267948966 0" xyz="0 0 -0.105"/>
            <geometry>
                <box size="0.24 0.02 0.018"/>
            </geometry>
        </collision>
    </link>

    <joint name="joint_HR3" type="revolute">
        <origin rpy="0 0 0" xyz="0 0 -0.2115"/>
        <parent link="link_HR2"/>
        <child link="link_HR3"/>
        <axis xyz="0 -1 0"/>
        <limit effort="18" lower="-2.3995" upper="2.5855" velocity="33"/>
        <dynamics damping="0.1" friction="0.5"/>
    </joint>

    <link name="link_HR4">
        <inertial>
            <origin rpy="0 0 0" xyz="0 0 0"/>
            <mass value="0"/>
            <inertia ixx="0" ixy="0" ixz="0" iyy="0" iyz="0" izz="0"/>
        </inertial>
        <visual>
            <origin rpy="0 0 0" xyz="0 0 0"/>
            <geometry>
                <sphere radius="0.001"/>
            </geometry>
        </visual>
        <collision>
            <origin rpy="0 0 0" xyz="0 0 0"/>
            <geometry>
                <sphere radius="0.025"/>
            </geometry>
        </collision>
    </link>

    <joint name="joint_HR4" type="fixed">
        <origin rpy="0 0 0" xyz="0 0 -0.24"/>
        <parent link="link_HR3"/>
        <child link="link_HR4"/>
    </joint>

    <link name="link_HRW">
        <inertial>
            <origin rpy="0 0 0" xyz="0 0 0"/>
            <mass value="0.120"/>
            <inertia ixx="0.000025" ixy="0" ixz="0" iyy="0.000040" iyz="0" izz="0.000025"/>
        </inertial>
        <visual>
            <origin rpy="0 0 0" xyz="0 0.02115 0"/>
            <geometry>
                <mesh filename="package://max/meshes/visual/link_HRW.STL"/>
            </geometry>
            <material name="">
                <color rgba="0.250980392156863 0.250980392156863 0.250980392156863 1"/>
            </material>
        </visual>
        <collision>
            <origin rpy="1.5707963267948966 0 0" xyz="0 0 0"/>
            <geometry>
                <cylinder length="0.016" radius="0.036"/>
            </geometry>
        </collision>
    </link>

    <joint name="joint_HRW" type="fixed">
        <origin rpy="0 1.5708 0" xyz="0 -0.04795 -0.2115"/>
        <parent link="link_HR2"/>
        <child link="link_HRW"/>
        <axis xyz="0 -1 0"/>
        <limit effort="18" lower="-214700000" upper="214700000" velocity="33"/>
        <dynamics damping="0.8" friction="0.5"/>
    </joint>

    <!-- HL leg -->
    <link name="link_HL1">
        <inertial>
            <origin rpy="0 0 0" xyz="0.0028696 -0.00034586 -0.00046692"/>
            <mass value="0.60318142"/>
            <inertia ixx="0.00036534" ixy="-0.00000156" ixz="0.00000493" iyy="0.00064755" iyz="-0.00000517"
                     izz="0.00041528"/>
        </inertial>
        <visual>
            <origin rpy="0 0 0" xyz="0 0 0"/>
            <geometry>
                <mesh filename="package://max/meshes/visual/link_HL1.STL"/>
            </geometry>
            <material name="">
                <color rgba="1 1 1 1"/>
            </material>
        </visual>
        <collision>
            <origin rpy="1.5707963267948966 0 0" xyz="0 0 0"/>
            <geometry>
                <cylinder length="0.0255" radius="0.047"/>
            </geometry>
        </collision>
    </link>

    <joint name="joint_HL1" type="revolute">
        <origin rpy="0 0 0" xyz="-0.195 0.06 0"/>
        <parent link="body"/>
        <child link="link_HL1"/>
        <axis xyz="1 0 0"/>
        <limit effort="18" lower="-0.697" upper="0.872" velocity="20"/>
        <dynamics damping="0.1" friction="0.5"/>
    </joint>

    <link name="link_HL2">
        <inertial>
            <origin rpy="0 0 0" xyz="-0.00077477 -0.02622481 -0.02560268"/>
            <mass value="0.89043408"/>
            <inertia ixx="0.00366698" ixy="0.00004816" ixz="0.00007841" iyy="0.00417229" iyz="-0.00046644"
                     izz="0.00119996"/>
        </inertial>
        <visual>
            <origin rpy="0 0 0" xyz="0 0 0"/>
            <geometry>
                <mesh filename="package://max/meshes/visual/link_HL2.STL"/>
            </geometry>
            <material name="">
                <color rgba="1 1 1 1"/>
            </material>
        </visual>
        <collision>
            <origin rpy="0 1.5707963267948966 0" xyz="0 0 -0.1"/>
            <geometry>
                <box size="0.2 0.025 0.035"/>
            </geometry>
        </collision>
        <collision>
            <origin rpy="1.5707963267948966 0 0" xyz="0 0 0"/>
            <geometry>
                <cylinder length="0.025" radius="0.023"/>
            </geometry>
        </collision>
        <collision>
            <origin rpy="1.5707963267948966 0 0" xyz="0 -0.030 0"/>
            <geometry>
                <cylinder length="0.025" radius="0.047"/>
            </geometry>
        </collision>
    </link>

    <joint name="joint_HL2" type="revolute">
        <origin rpy="0 0 0" xyz="0 0.09 0"/>
        <parent link="link_HL1"/>
        <child link="link_HL2"/>
        <axis xyz="0 -1 0"/>
        <limit effort="18" lower="-4.3633" upper="1.2217" velocity="20"/>
        <dynamics damping="0.1" friction="0.5"/>
    </joint>

    <link name="link_HL3">
        <inertial>
            <origin rpy="0 0 0" xyz="0.00171417901871168 0.000158421724618441 -0.0867126641820617"/>
            <mass value="0.28839466"/>
            <inertia ixx="0.00208102" ixy="0.00000004" ixz="0.00008280" iyy="0.00209717" iyz="0.00000423"
                     izz="0.00006551"/>
        </inertial>
        <visual>
            <origin rpy="0 0 0" xyz="0 0 0"/>
            <geometry>
                <mesh filename="package://max/meshes/visual/link_HL3.STL"/>
            </geometry>
            <material name="">
                <color rgba="1 1 1 1"/>
            </material>
        </visual>
        <collision>
            <origin rpy="0 1.5707963267948966 0" xyz="0 0 -0.105"/>
            <geometry>
                <box size="0.24 0.02 0.018"/>
            </geometry>
        </collision>
    </link>

    <joint name="joint_HL3" type="revolute">
        <origin rpy="0 0 0" xyz="0 0 -0.2115"/>
        <parent link="link_HL2"/>
        <child link="link_HL3"/>
        <axis xyz="0 -1 0"/>
        <limit effort="18" lower="-2.3995" upper="2.5855" velocity="33"/>
        <dynamics damping="0.1" friction="0.5"/>
    </joint>

    <link name="link_HL4">
        <inertial>
            <origin rpy="0 0 0" xyz="0 0 0"/>
            <mass value="0"/>
            <inertia ixx="0" ixy="0" ixz="0" iyy="0" iyz="0" izz="0"/>
        </inertial>
        <visual>
            <origin rpy="0 0 0" xyz="0 0 0"/>
            <geometry>
                <sphere radius="0.001"/>
            </geometry>
        </visual>
        <collision>
            <origin rpy="0 0 0" xyz="0 0 0"/>
            <geometry>
                <sphere radius="0.025"/>
            </geometry>
        </collision>
    </link>

    <joint name="joint_HL4" type="fixed">
        <origin rpy="0 0 0" xyz="0 0 -0.24"/>
        <parent link="link_HL3"/>
        <child link="link_HL4"/>
    </joint>

    <link name="link_HLW">
        <inertial>
            <origin rpy="0 0 0" xyz="0 0 0"/>
            <mass value="0.120"/>
            <inertia ixx="0.000025" ixy="0" ixz="0" iyy="0.000040" iyz="0" izz="0.000025"/>
        </inertial>
        <visual>
            <origin rpy="0 0 0" xyz="0 -0.02115 0"/>
            <geometry>
                <mesh filename="package://max/meshes/visual/link_HLW.STL"/>
            </geometry>
            <material name="">
                <color rgba="0.250980392156863 0.250980392156863 0.250980392156863 1"/>
            </material>
        </visual>
        <collision>
            <origin rpy="1.5707963267948966 0 0" xyz="0 0 0"/>
            <geometry>
                <cylinder length="0.016" radius="0.036"/>
            </geometry>
        </collision>
    </link>

    <joint name="joint_HLW" type="fixed">
        <origin rpy="0 1.5708 0" xyz="0 0.04795 -0.2115"/>
        <parent link="link_HL2"/>
        <child link="link_HLW"/>
        <axis xyz="0 -1 0"/>
        <limit effort="18" lower="-214700000" upper="214700000" velocity="33"/>
        <dynamics damping="0.8" friction="0.5"/>
    </joint>

    <!-- Front Handle -->
    <link name="link_front_handle">
        <inertial>
            <origin rpy="0 0 0" xyz="0 0 0"/>
            <mass value="0.001"/>
            <inertia ixx="0" ixy="0" ixz="0" iyy="0" iyz="0" izz="0"/>
        </inertial>
        <collision>
            <origin rpy="0 0 0" xyz="0 0 0"/>
            <geometry>
                <sphere radius="0.001"/>
            </geometry>
        </collision>
    </link>

    <joint name="joint_front_handle" type="fixed">
        <origin rpy="0 0 0" xyz="0.1415 0 0.085"/>
        <parent link="body"/>
        <child link="link_front_handle"/>
    </joint>

    <!-- Hind Handle -->
    <link name="link_hind_handle">
        <inertial>
            <origin rpy="0 0 0" xyz="0 0 0"/>
            <mass value="0.001"/>
            <inertia ixx="0" ixy="0" ixz="0" iyy="0" iyz="0" izz="0"/>
        </inertial>
        <collision>
            <origin rpy="0 0 0" xyz="0 0 0"/>
            <geometry>
                <sphere radius="0.001"/>
            </geometry>
        </collision>
    </link>

    <joint name="joint_hind_handle" type="fixed">
        <origin rpy="0 0 0" xyz="-0.2485 0 0.085"/>
        <parent link="body"/>
        <child link="link_hind_handle"/>
    </joint>

</robot>
